Workbook
Name CY_calc: '1. MPFS FFS Model'!#REF!
Name CY_calc: '2. Premiums and MA Model'!$49:$72
Name CY_check: '1. MPFS FFS Model'!#REF!
Name CY_check: '2. Premiums and MA Model'!$73:$95
Name FY_calc: '1. MPFS FFS Model'!#REF!
Name FY_calc: '2. Premiums and MA Model'!#REF!
Name FY_check: '1. MPFS FFS Model'!#REF!
Name FY_check: '2. Premiums and MA Model'!#REF!

Sheet README
B52: Table of Contents
B54: Tab | F54: Type | I54: Purpose
B55: README | F55: Reference | I55: Overview of Model Workbook
B56: Summary | F56: Input, Output | I56: Input policy parameters and timing, output estimate
B57: 1. MPFS FFS Model | F57: Calculations | I57: Calculate effect on MPFS FFS federal spending
B58: 2. Premiums and MA Model | F58: Calculations | I58: Calculate effect on premium receipts and MA spending
B59: License | F59: License | I59: License, disclaimers, disclosures
B61: Abbreviations Used in This Model
B63: APM | C63: Alternative Payment Model
B64: CY | C64: calendar year
B65: FFS | C65: fee-for-service
B66: FY | C66: fiscal year
B67: MA | C67: Medicare Advantage
B68: MPFS | C68: Medicare physician fee schedule

Sheet Summary
B2: Model Summary
B4: 1) Policy Parameters
B5: 2) Estimate
B6: 3) Memo Lines: Conversion factors under current and proposed law
B8: =B4 -> 1) Policy Parameters
B9: Calendar Year | E9: 2026 | F9: =E9+1 -> 2027 | G9: =F9+1 -> 2028 | H9: =G9+1 -> 2029 | I9: =H9+1 -> 2030 | J9: =I9+1 -> 2031 | K9: =J9+1 -> 2032 | L9: =K9+1 -> 2033 | M9: =L9+1 -> 2034 | ... O9: =N9+1 -> 2036
B11: Instructions:
B12: Enter % temporary change to the conversion factor by calendar year.
B13: This model supports policy changes for a full calendar year only.
B14: This model projects the budgetary effects of temporary changes to the conversion factor of around 2.5%. Inputs that are substantially larger or smaller than 2.5% may not produce reliable outputs.
B16: Policy Parameter: Temproary change in the MPFS conversion factor | E16: 0 | F16: 0.025 | G16: 0 | H16: 0 | I16: 0 | J16: 0 | K16: 0 | L16: 0 | M16: 0 | N16: 0 | O16: 0
B18: =B5 -> 2) Estimate
B19: Fiscal Year | E19: 2026 | F19: 2027 | G19: 2028 | H19: 2029 | I19: 2030 | J19: 2031 | K19: 2032 | L19: 2033 | M19: 2034 | N19: 2035 | O19: 2036 | Q19: 2026-2031 | R19: 2026-2036
B20: Error check: | C20: =IF(COUNTIF('2. Premiums and MA Model'!F86:P86,"=FAIL")>0,"FAIL, See Premiums and MA Model Tab","PASS") -> PASS
B22: Effect on FFS Benefit Spending | E22: ='2. Premiums and MA Model'!F89 -> 0 | F22: ='2. Premiums and MA Model'!G89 -> 1631 | G22: ='2. Premiums and MA Model'!H89 -> 1112 | H22: ='2. Premiums and MA Model'!I89 -> 0 | I22: ='2. Premiums and MA Model'!J89 -> 0 | J22: ='2. Premiums and MA Model'!K89 -> 0 | K22: ='2. Premiums and MA Model'!L89 -> 0 | L22: ='2. Premiums and MA Model'!M89 -> 0 | ... O22: ='2. Premiums and MA Model'!P89 -> 0 | Q22: =SUM(E22:J22) -> 2743 | R22: =SUM(E22:O22) -> 2743
B23: Effect on MA Benefit Spending | E23: ='2. Premiums and MA Model'!F90 -> 0 | F23: ='2. Premiums and MA Model'!G90 -> 2653 | G23: ='2. Premiums and MA Model'!H90 -> 884 | H23: ='2. Premiums and MA Model'!I90 -> 0 | I23: ='2. Premiums and MA Model'!J90 -> 0 | J23: ='2. Premiums and MA Model'!K90 -> 0 | K23: ='2. Premiums and MA Model'!L90 -> 0 | L23: ='2. Premiums and MA Model'!M90 -> 0 | ... O23: ='2. Premiums and MA Model'!P90 -> 0 | Q23: =SUM(E23:J23) -> 3537 | R23: =SUM(E23:O23) -> 3537
B24: Effect on Part B Premium Receipts | E24: ='2. Premiums and MA Model'!F94 -> 0 | F24: ='2. Premiums and MA Model'!G94 -> -1225 | G24: ='2. Premiums and MA Model'!H94 -> -408 | H24: ='2. Premiums and MA Model'!I94 -> 0 | I24: ='2. Premiums and MA Model'!J94 -> 0 | J24: ='2. Premiums and MA Model'!K94 -> 0 | K24: ='2. Premiums and MA Model'!L94 -> 0 | L24: ='2. Premiums and MA Model'!M94 -> 0 | ... O24: ='2. Premiums and MA Model'!P94 -> 0 | Q24: =SUM(E24:J24) -> -1633 | R24: =SUM(E24:O24) -> -1633
B26: Total Effect
B27: Budget Authority | E27: ='2. Premiums and MA Model'!F97 -> 0 | F27: ='2. Premiums and MA Model'!G97 -> 3059 | G27: ='2. Premiums and MA Model'!H97 -> 1588 | H27: ='2. Premiums and MA Model'!I97 -> 0 | I27: ='2. Premiums and MA Model'!J97 -> 0 | J27: ='2. Premiums and MA Model'!K97 -> 0 | K27: ='2. Premiums and MA Model'!L97 -> 0 | L27: ='2. Premiums and MA Model'!M97 -> 0 | ... O27: ='2. Premiums and MA Model'!P97 -> 0 | Q27: =SUM(E27:J27) -> 4647 | R27: =SUM(E27:O27) -> 4647
B28: Outlays | E28: ='2. Premiums and MA Model'!F98 -> 0 | F28: ='2. Premiums and MA Model'!G98 -> 3059 | G28: ='2. Premiums and MA Model'!H98 -> 1588 | H28: ='2. Premiums and MA Model'!I98 -> 0 | I28: ='2. Premiums and MA Model'!J98 -> 0 | J28: ='2. Premiums and MA Model'!K98 -> 0 | K28: ='2. Premiums and MA Model'!L98 -> 0 | L28: ='2. Premiums and MA Model'!M98 -> 0 | ... O28: ='2. Premiums and MA Model'!P98 -> 0 | Q28: =SUM(E28:J28) -> 4647 | R28: =SUM(E28:O28) -> 4647
B31: =B6 -> 3) Memo Lines: Conversion factors under current and proposed law
B32: Description | C32: Notes | E32: 2026 | F32: =E32+1 -> 2027 | G32: =F32+1 -> 2028 | H32: =G32+1 -> 2029 | I32: =H32+1 -> 2030 | J32: =I32+1 -> 2031 | K32: =J32+1 -> 2032 | L32: =K32+1 -> 2033 | M32: =L32+1 -> 2034 | ... O32: =N32+1 -> 2036 | Q32: 2026-2031 | R32: 2026-2036
B34: Qualifying APM Participants | C34: 1.0075
B35: Other Providers | C35: 1.0025
B36: 2026 Bump | C36: 0.025
B38: Calendar Year Conversion Factors
B39: Current Law
B40: Qualifying APM Participants | E40: 33.57 | F40: =1.0075*E40/(1+C36) -> 32.996854 | G40: =F40*$C$34 -> 33.24433 | H40: =G40*$C$34 -> 33.493663 | I40: =H40*$C$34 -> 33.744865 | J40: =I40*$C$34 -> 33.997951 | K40: =J40*$C$34 -> 34.252936 | L40: =K40*$C$34 -> 34.509833 | M40: =L40*$C$34 -> 34.768657 | N40: =M40*$C$34 -> 35.029422 | O40: =N40*$C$34 -> 35.292142
B41: Other Providers | E41: 33.4 | F41: =C35*E41/(1+C36) -> 32.666829 | G41: =F41*$C$35 -> 32.748496 | H41: =G41*$C$35 -> 32.830368 | I41: =H41*$C$35 -> 32.912444 | J41: =I41*$C$35 -> 32.994725 | K41: =J41*$C$35 -> 33.077211 | L41: =K41*$C$35 -> 33.159904 | M41: =L41*$C$35 -> 33.242804 | N41: =M41*$C$35 -> 33.325911 | O41: =N41*$C$35 -> 33.409226
B42: Proposed Law
B43: Qualifying APM Participants | E43: =E40*(1+E$16) -> 33.57 | F43: =F40*(1+F$16) -> 33.821775 | G43: =G40*(1+G$16) -> 33.24433 | H43: =H40*(1+H$16) -> 33.493663 | I43: =I40*(1+I$16) -> 33.744865 | J43: =J40*(1+J$16) -> 33.997951 | K43: =K40*(1+K$16) -> 34.252936 | L43: =L40*(1+L$16) -> 34.509833 | ... O43: =O40*(1+O$16) -> 35.292142
B44: Other Providers | E44: =E41*(1+E$16) -> 33.4 | F44: =F41*(1+F$16) -> 33.4835 | G44: =G41*(1+G$16) -> 32.748496 | H44: =H41*(1+H$16) -> 32.830368 | I44: =I41*(1+I$16) -> 32.912444 | J44: =J41*(1+J$16) -> 32.994725 | K44: =K41*(1+K$16) -> 33.077211 | L44: =L41*(1+L$16) -> 33.159904 | ... O44: =O41*(1+O$16) -> 33.409226
B46: Incurred CY budgetary effect*
B47: Effect on FFS Benefit Spending | E47: =ROUND('2. Premiums and MA Model'!F16,0) -> 0 | F47: =ROUND('2. Premiums and MA Model'!G16,0) -> 2743 | G47: =ROUND('2. Premiums and MA Model'!H16,0) -> 0 | H47: =ROUND('2. Premiums and MA Model'!I16,0) -> 0 | I47: =ROUND('2. Premiums and MA Model'!J16,0) -> 0 | J47: =ROUND('2. Premiums and MA Model'!K16,0) -> 0 | K47: =ROUND('2. Premiums and MA Model'!L16,0) -> 0 | L47: =ROUND('2. Premiums and MA Model'!M16,0) -> 0 | ... O47: =ROUND('2. Premiums and MA Model'!P16,0) -> 0 | Q47: =SUM(E47:J47) -> 2743 | R47: =SUM(E47:O47) -> 2743
B48: Effect on MA Benefit Spending | E48: =ROUND('2. Premiums and MA Model'!F57,0) -> 0 | F48: =ROUND('2. Premiums and MA Model'!G57,0) -> 3538 | G48: =ROUND('2. Premiums and MA Model'!H57,0) -> 0 | H48: =ROUND('2. Premiums and MA Model'!I57,0) -> 0 | I48: =ROUND('2. Premiums and MA Model'!J57,0) -> 0 | J48: =ROUND('2. Premiums and MA Model'!K57,0) -> 0 | K48: =ROUND('2. Premiums and MA Model'!L57,0) -> 0 | L48: =ROUND('2. Premiums and MA Model'!M57,0) -> 0 | ... O48: =ROUND('2. Premiums and MA Model'!P57,0) -> 0 | Q48: =SUM(E48:J48) -> 3538 | R48: =SUM(E48:O48) -> 3538
B49: Effect on Part B Premium Receipts | E49: =ROUND('2. Premiums and MA Model'!F68,0) -> 0 | F49: =ROUND('2. Premiums and MA Model'!G68,0) -> -1633 | G49: =ROUND('2. Premiums and MA Model'!H68,0) -> 0 | H49: =ROUND('2. Premiums and MA Model'!I68,0) -> 0 | I49: =ROUND('2. Premiums and MA Model'!J68,0) -> 0 | J49: =ROUND('2. Premiums and MA Model'!K68,0) -> 0 | K49: =ROUND('2. Premiums and MA Model'!L68,0) -> 0 | L49: =ROUND('2. Premiums and MA Model'!M68,0) -> 0 | ... O49: =ROUND('2. Premiums and MA Model'!P68,0) -> 0 | Q49: =SUM(E49:J49) -> -1633 | R49: =SUM(E49:O49) -> -1633
B50: Overall effect | E50: =SUM(E47:E49) -> 0 | F50: =SUM(F47:F49) -> 4648 | G50: =SUM(G47:G49) -> 0 | H50: =SUM(H47:H49) -> 0 | I50: =SUM(I47:I49) -> 0 | J50: =SUM(J47:J49) -> 0 | K50: =SUM(K47:K49) -> 0 | L50: =SUM(L47:L49) -> 0 | ... O50: =SUM(O47:O49) -> 0 | Q50: =SUM(E50:J50) -> 4648 | R50: =SUM(E50:O50) -> 4648
B51: *Components may not sum to totals because of rounding.

Sheet 1. MPFS FFS Model
B2: 1. MPFS FFS Model
B4: 1) Policy Parameters
B5: 2) CBO Inputs
B6: 3) Calculation of MPFS spending changes
B7: 4) Summary of FFS spending changes
B9: =B4 -> 1) Policy Parameters
B10: Description | C10: Notes | E10: 2026 | F10: =E10+1 -> 2027 | G10: =F10+1 -> 2028 | H10: =G10+1 -> 2029 | I10: =H10+1 -> 2030 | J10: =I10+1 -> 2031 | K10: =J10+1 -> 2032 | L10: =K10+1 -> 2033 | M10: =L10+1 -> 2034 | ... O10: =N10+1 -> 2036 | Q10: 2026-2031 | R10: 2026-2036
B12: Policy Parameter: Temporary Change in the MPFS Conversion Factor (CY) | E12: =Summary!E16 -> 0 | F12: =Summary!F16 -> 0.025 | G12: =Summary!G16 -> 0 | H12: =Summary!H16 -> 0 | I12: =Summary!I16 -> 0 | J12: =Summary!J16 -> 0 | K12: =Summary!K16 -> 0 | L12: =Summary!L16 -> 0 | ... O12: =Summary!O16 -> 0
B14: =B5 -> 2) CBO Inputs
B15: Description | C15: Notes | E15: 2026 | F15: =E15+1 -> 2027 | G15: =F15+1 -> 2028 | H15: =G15+1 -> 2029 | I15: =H15+1 -> 2030 | J15: =I15+1 -> 2031 | K15: =J15+1 -> 2032 | L15: =K15+1 -> 2033 | M15: =L15+1 -> 2034 | ... O15: =N15+1 -> 2036 | Q15: 2026-2031 | R15: 2026-2036
B17: CBO's February 2026 Baseline: MPFS FFS (Millions, CY) | E17: 75799.236 | F17: 75075.179 | G17: 76059.679 | H17: 78136.615 | I17: 80473.035 | J17: 82735.835 | K17: 85086.811 | L17: 88678.474 | M17: 92005.971 | N17: 95025.863 | O17: 97973.006 | Q17: =SUM(E17:J17) -> 468279.58 | R17: =SUM(E17:O17) -> 927049.71
B19: Supply Elasticity (Elasticity per 1 percentage point decrease in price) | C19: Source: Exhibit 4-2 https://www.cbo.gov/system/files/2020-12/56811-Single-Payer.pdf#page=54 | D19: 0.45
B21: =B6 -> 3) Calculation of MPFS spending changes
B22: Description | C22: Notes | E22: 2026 | F22: =E22+1 -> 2027 | G22: =F22+1 -> 2028 | H22: =G22+1 -> 2029 | I22: =H22+1 -> 2030 | J22: =I22+1 -> 2031 | K22: =J22+1 -> 2032 | L22: =K22+1 -> 2033 | M22: =L22+1 -> 2034 | ... O22: =N22+1 -> 2036 | Q22: 2026-2031 | R22: 2026-2036
B24: MPFS spending after payment change, before behavioral response | E24: =E17*(1+E12) -> 75799.236 | F24: =F17*(1+F12) -> 76952.059 | G24: =G17*(1+G12) -> 76059.679 | H24: =H17*(1+H12) -> 78136.615 | I24: =I17*(1+I12) -> 80473.035 | J24: =J17*(1+J12) -> 82735.835 | K24: =K17*(1+K12) -> 85086.811 | L24: =L17*(1+L12) -> 88678.474 | ... O24: =O17*(1+O12) -> 97973.006 | Q24: =SUM(E24:J24) -> 470156.46 | R24: =SUM(E24:O24) -> 928926.58
B25: Difference from current law baseline (Millions, CY) | E25: =E24-E17 -> 0 | F25: =F24-F17 -> 1876.8795 | G25: =G24-G17 -> 0 | H25: =H24-H17 -> 0 | I25: =I24-I17 -> 0 | J25: =J24-J17 -> 0 | K25: =K24-K17 -> 0 | L25: =L24-L17 -> 0 | ... O25: =O24-O17 -> 0 | Q25: =SUM(E25:J25) -> 1876.8795 | R25: =SUM(E25:O25) -> 1876.8795
B27: Supply elasticity for behavioral response | E27: =IF(E12<>0,$D$19*E12,0) -> 0 | F27: =IF(F12<>0,$D$19*F12,0) -> 0.01125 | G27: =IF(G12<>0,$D$19*G12,0) -> 0 | H27: =IF(H12<>0,$D$19*H12,0) -> 0 | I27: =IF(I12<>0,$D$19*I12,0) -> 0 | J27: =IF(J12<>0,$D$19*J12,0) -> 0 | K27: =IF(K12<>0,$D$19*K12,0) -> 0 | L27: =IF(L12<>0,$D$19*L12,0) -> 0 | ... O27: =IF(O12<>0,$D$19*O12,0) -> 0
B29: MPFS spending after payment change, after behavioral response | E29: =E24*(1+E27) -> 75799.236 | F29: =F24*(1+F27) -> 77817.769 | G29: =G24*(1+G27) -> 76059.679 | H29: =H24*(1+H27) -> 78136.615 | I29: =I24*(1+I27) -> 80473.035 | J29: =J24*(1+J27) -> 82735.835 | K29: =K24*(1+K27) -> 85086.811 | L29: =L24*(1+L27) -> 88678.474 | ... O29: =O24*(1+O27) -> 97973.006 | Q29: =SUM(E29:J29) -> 471022.17 | R29: =SUM(E29:O29) -> 929792.3
B30: Difference from current law baseline (Millions, CY) | E30: =E29-E17 -> 0 | F30: =F29-F17 -> 2742.5901 | G30: =G29-G17 -> 0 | H30: =H29-H17 -> 0 | I30: =I29-I17 -> 0 | J30: =J29-J17 -> 0 | K30: =K29-K17 -> 0 | L30: =L29-L17 -> 0 | ... O30: =O29-O17 -> 0 | Q30: =SUM(E30:J30) -> 2742.5901 | R30: =SUM(E30:O30) -> 2742.5901
B32: =B7 -> 4) Summary of FFS spending changes
B33: Description | C33: Notes | E33: 2026 | F33: =E33+1 -> 2027 | G33: =F33+1 -> 2028 | H33: =G33+1 -> 2029 | I33: =H33+1 -> 2030 | J33: =I33+1 -> 2031 | K33: =J33+1 -> 2032 | L33: =K33+1 -> 2033 | M33: =L33+1 -> 2034 | ... O33: =N33+1 -> 2036 | Q33: 2026-2031 | R33: 2026-2036
B35: Change in MPFS FFS spending due to payment change | E35: =E25 -> 0 | F35: =F25 -> 1876.8795 | G35: =G25 -> 0 | H35: =H25 -> 0 | I35: =I25 -> 0 | J35: =J25 -> 0 | K35: =K25 -> 0 | L35: =L25 -> 0 | ... O35: =O25 -> 0 | Q35: =SUM(E35:J35) -> 1876.8795 | R35: =SUM(E35:O35) -> 1876.8795
B36: Change in MPFS FFS spending due to behavioral response | E36: =E30-E25 -> 0 | F36: =F30-F25 -> 865.71066 | G36: =G30-G25 -> 0 | H36: =H30-H25 -> 0 | I36: =I30-I25 -> 0 | J36: =J30-J25 -> 0 | K36: =K30-K25 -> 0 | L36: =L30-L25 -> 0 | ... O36: =O30-O25 -> 0 | Q36: =SUM(E36:J36) -> 865.71066 | R36: =SUM(E36:O36) -> 865.71066
B37: Total change in MPFS FFS spending associated with policy (Millions, CY, incurred) | E37: =E30 -> 0 | F37: =F30 -> 2742.5901 | G37: =G30 -> 0 | H37: =H30 -> 0 | I37: =I30 -> 0 | J37: =J30 -> 0 | K37: =K30 -> 0 | L37: =L30 -> 0 | ... O37: =O30 -> 0 | Q37: =SUM(E37:J37) -> 2742.5901 | R37: =SUM(E37:O37) -> 2742.5901

Sheet 2. Premiums and MA Model
B2: 2. Premiums and MA Model
B4: 1) Inputs
B5: 2) Calculations | R5: 2026 | S5: 2026
B6: 3) Checks | R6: 2031 | S6: 2036
B7: 4) Output: FY Cash Estimate
B9: =$B$4 -> 1) Inputs
B10: 1a) Policy Inputs
B12: Policy Start Date (inclusive) | C12: {=DATE(_xlfn.XLOOKUP(TRUE,'1. MPFS FFS Model'!E12:O12<>0,'1. MPFS FFS Model'!E10:O10,Summary!E10,0,1),1,1)} -> 46388
B13: Policy End Date (inclusive) | C13: {=DATE(_xlfn.XLOOKUP(TRUE,'1. MPFS FFS Model'!E12:O12<>0,'1. MPFS FFS Model'!E10:O10,Summary!O9,0,-1),12,31)} -> 46752
B15: Description | C15: FY/CY Input | D15: Note | F15: 2026 | G15: =F15+1 -> 2027 | H15: =G15+1 -> 2028 | I15: =H15+1 -> 2029 | J15: =I15+1 -> 2030 | K15: =J15+1 -> 2031 | L15: =K15+1 -> 2032 | M15: =L15+1 -> 2033 | N15: =M15+1 -> 2034 | ... P15: =O15+1 -> 2036 | R15: =_xlfn.CONCAT($R$5,"-", $R$6) -> 2026-2031 | S15: =_xlfn.CONCAT($S$5, "-", $S$6) -> 2026-2036
B16: FFS Estimate Incurred (millions) | C16: CY | F16: ='1. MPFS FFS Model'!E37 -> 0 | G16: ='1. MPFS FFS Model'!F37 -> 2742.5901 | H16: ='1. MPFS FFS Model'!G37 -> 0 | I16: ='1. MPFS FFS Model'!H37 -> 0 | J16: ='1. MPFS FFS Model'!I37 -> 0 | K16: ='1. MPFS FFS Model'!J37 -> 0 | L16: ='1. MPFS FFS Model'!K37 -> 0 | M16: ='1. MPFS FFS Model'!L37 -> 0 | ... P16: ='1. MPFS FFS Model'!O37 -> 0 | R16: =SUM(_xlfn.XLOOKUP($R$5, $15:$15, $16:$16, "", 0):_xlfn.XLOOKUP($R$6, $15:$15, $16:$16, "", 0)) -> 2742.5901 | S16: =SUM(_xlfn.XLOOKUP($S$5, $15:$15, $16:$16, "", 0):_xlfn.XLOOKUP($S$6, $15:$15, $16:$16, "", 0)) -> 2742.5901
B18: Interactions to Apply
B19: Part A MA Interaction Term | C19: 0
B20: Part B MA Interaction Term | C20: 1
B21: Part B Premium Interaction Term | C21: 1
B22: Cash Lag (Days) | C22: 56
B23: Last Year of Published MA Rates | C23: 2026
B24: Last Year of Published Part B Premiums | C24: 2026
B26: 1b) Baseline Inputs
B27: Description | C27: On/Off Switch | F27: =F$15 -> 2026 | G27: =G$15 -> 2027 | H27: =H$15 -> 2028 | I27: =I$15 -> 2029 | J27: =J$15 -> 2030 | K27: =K$15 -> 2031 | L27: =L$15 -> 2032 | M27: =M$15 -> 2033 | ... P27: =P$15 -> 2036
B28: Part A MA Interaction Term (Percent, CY) | C28: =C19 -> 0 | F28: 0 | G28: 1.16 | H28: 1.21 | I28: 1.25 | J28: 1.29 | K28: 1.33 | L28: 1.35 | M28: 1.39 | N28: 1.41 | O28: 1.43 | P28: 1.45
B29: Part B MA Interaction Term (Percent, CY) | C29: =C20 -> 1 | F29: 0 | G29: 1.29 | H29: 1.35 | I29: 1.41 | J29: 1.46 | K29: 1.51 | L29: 1.54 | M29: 1.59 | N29: 1.62 | O29: 1.64 | P29: 1.67
B30: Part B Premium Interaction Term (Percent, CY) | C30: =C21 -> 1 | F30: -0.26 | G30: -0.26 | H30: -0.26 | I30: -0.25 | J30: -0.26 | K30: -0.26 | L30: -0.26 | M30: -0.26 | N30: -0.26 | O30: -0.26 | P30: -0.26
B31: =IF(C28+C29=2, "Error: Only one MA Interaction term may be selected.", "Confirmed: One or fewer MA Interaction terms was selected.") -> Confirmed: One or fewer MA Interaction terms was selected.
B33: =$B$5 -> 2) Calculations
B34: 2a) Allocate FFS CY Incurred Spending as a Share of FY Cash
B35: Description | C35: Notes | F35: =F$15 -> 2026 | G35: =G$15 -> 2027 | H35: =H$15 -> 2028 | I35: =I$15 -> 2029 | J35: =J$15 -> 2030 | K35: =K$15 -> 2031 | L35: =L$15 -> 2032 | M35: =M$15 -> 2033 | ... P35: =P$15 -> 2036 | R35: =R$15 -> 2026-2031 | S35: =S$15 -> 2026-2036
B36: Early CY Cash
B37: FY Cash Start Date within Matching FY | F37: =DATE(F$15,1,1) -> 46023 | G37: =DATE(G$15,1,1) -> 46388 | H37: =DATE(H$15,1,1) -> 46753 | I37: =DATE(I$15,1,1) -> 47119 | J37: =DATE(J$15,1,1) -> 47484 | K37: =DATE(K$15,1,1) -> 47849 | L37: =DATE(L$15,1,1) -> 48214 | M37: =DATE(M$15,1,1) -> 48580 | ... P37: =DATE(P$15,1,1) -> 49675
B38: Matching FY End Date | F38: =DATE(F$15,9,30) -> 46295 | G38: =DATE(G$15,9,30) -> 46660 | H38: =DATE(H$15,9,30) -> 47026 | I38: =DATE(I$15,9,30) -> 47391 | J38: =DATE(J$15,9,30) -> 47756 | K38: =DATE(K$15,9,30) -> 48121 | L38: =DATE(L$15,9,30) -> 48487 | M38: =DATE(M$15,9,30) -> 48852 | ... P38: =DATE(P$15,9,30) -> 49948
B39: FY Cash End Date, lagged from Next FY | F39: =F$38-$C$22 -> 46239 | G39: =G$38-$C$22 -> 46604 | H39: =H$38-$C$22 -> 46970 | I39: =I$38-$C$22 -> 47335 | J39: =J$38-$C$22 -> 47700 | K39: =K$38-$C$22 -> 48065 | L39: =L$38-$C$22 -> 48431 | M39: =M$38-$C$22 -> 48796 | ... P39: =P$38-$C$22 -> 49892
B40: Late CY Cash
B41: FY Cash Start Date, lagged from Next FY | F41: =F$39+1 -> 46240 | G41: =G$39+1 -> 46605 | H41: =H$39+1 -> 46971 | I41: =I$39+1 -> 47336 | J41: =J$39+1 -> 47701 | K41: =K$39+1 -> 48066 | L41: =L$39+1 -> 48432 | M41: =M$39+1 -> 48797 | ... P41: =P$39+1 -> 49893
B42: FY Cash End Date within Next FY | F42: =DATE(F$15,12,31) -> 46387 | G42: =DATE(G$15,12,31) -> 46752 | H42: =DATE(H$15,12,31) -> 47118 | I42: =DATE(I$15,12,31) -> 47483 | J42: =DATE(J$15,12,31) -> 47848 | K42: =DATE(K$15,12,31) -> 48213 | L42: =DATE(L$15,12,31) -> 48579 | M42: =DATE(M$15,12,31) -> 48944 | ... P42: =DATE(P$15,12,31) -> 50040
B43: Number of Effective Days within CY in Early FY Cash (Jan-Sept) | F43: {=_xlfn.IFS(AND($C$12>=F$37,$C$13<=F$39),$C$13-$C$12+1,OR(F$39<$C$12,F$37>$C$13),0,AND(F$37>$C$12,F$39<$C$13),F$39-F$37+1,F$37<=$C$12,F$39-$C$12+1,F$39>=$C$13,$C$13-F$37+1)} -> 0 | G43: {=_xlfn.IFS(AND($C$12>=G$37,$C$13<=G$39),$C$13-$C$12+1,OR(G$39<$C$12,G$37>$C$13),0,AND(G$37>$C$12,G$39<$C$13),G$39-G$37+1,G$37<=$C$12,G$39-$C$12+1,G$39>=$C$13,$C$13-G$37+1)} -> 217 | H43: {=_xlfn.IFS(AND($C$12>=H$37,$C$13<=H$39),$C$13-$C$12+1,OR(H$39<$C$12,H$37>$C$13),0,AND(H$37>$C$12,H$39<$C$13),H$39-H$37+1,H$37<=$C$12,H$39-$C$12+1,H$39>=$C$13,$C$13-H$37+1)} -> 0 | I43: {=_xlfn.IFS(AND($C$12>=I$37,$C$13<=I$39),$C$13-$C$12+1,OR(I$39<$C$12,I$37>$C$13),0,AND(I$37>$C$12,I$39<$C$13),I$39-I$37+1,I$37<=$C$12,I$39-$C$12+1,I$39>=$C$13,$C$13-I$37+1)} -> 0 | J43: {=_xlfn.IFS(AND($C$12>=J$37,$C$13<=J$39),$C$13-$C$12+1,OR(J$39<$C$12,J$37>$C$13),0,AND(J$37>$C$12,J$39<$C$13),J$39-J$37+1,J$37<=$C$12,J$39-$C$12+1,J$39>=$C$13,$C$13-J$37+1)} -> 0 | K43: {=_xlfn.IFS(AND($C$12>=K$37,$C$13<=K$39),$C$13-$C$12+1,OR(K$39<$C$12,K$37>$C$13),0,AND(K$37>$C$12,K$39<$C$13),K$39-K$37+1,K$37<=$C$12,K$39-$C$12+1,K$39>=$C$13,$C$13-K$37+1)} -> 0 | L43: {=_xlfn.IFS(AND($C$12>=L$37,$C$13<=L$39),$C$13-$C$12+1,OR(L$39<$C$12,L$37>$C$13),0,AND(L$37>$C$12,L$39<$C$13),L$39-L$37+1,L$37<=$C$12,L$39-$C$12+1,L$39>=$C$13,$C$13-L$37+1)} -> 0 | M43: {=_xlfn.IFS(AND($C$12>=M$37,$C$13<=M$39),$C$13-$C$12+1,OR(M$39<$C$12,M$37>$C$13),0,AND(M$37>$C$12,M$39<$C$13),M$39-M$37+1,M$37<=$C$12,M$39-$C$12+1,M$39>=$C$13,$C$13-M$37+1)} -> 0 | ... P43: {=_xlfn.IFS(AND($C$12>=P$37,$C$13<=P$39),$C$13-$C$12+1,OR(P$39<$C$12,P$37>$C$13),0,AND(P$37>$C$12,P$39<$C$13),P$39-P$37+1,P$37<=$C$12,P$39-$C$12+1,P$39>=$C$13,$C$13-P$37+1)} -> 0
B44: Number of Effective Days within CY in Late FY Cash (Oct-Dec) | F44: {=_xlfn.IFS(AND($C$12>=F$41,$C$13<=F$42),$C$13-$C$12+1,OR(F$42<$C$12,F$41>$C$13),0,AND(F$41>$C$12,F$42<$C$13),F$42-F$41+1,F$41<=$C$12,F$42-$C$12+1,F$42>=$C$13,$C$13-F$41+1)} -> 0 | G44: {=_xlfn.IFS(AND($C$12>=G$41,$C$13<=G$42),$C$13-$C$12+1,OR(G$42<$C$12,G$41>$C$13),0,AND(G$41>$C$12,G$42<$C$13),G$42-G$41+1,G$41<=$C$12,G$42-$C$12+1,G$42>=$C$13,$C$13-G$41+1)} -> 148 | H44: {=_xlfn.IFS(AND($C$12>=H$41,$C$13<=H$42),$C$13-$C$12+1,OR(H$42<$C$12,H$41>$C$13),0,AND(H$41>$C$12,H$42<$C$13),H$42-H$41+1,H$41<=$C$12,H$42-$C$12+1,H$42>=$C$13,$C$13-H$41+1)} -> 0 | I44: {=_xlfn.IFS(AND($C$12>=I$41,$C$13<=I$42),$C$13-$C$12+1,OR(I$42<$C$12,I$41>$C$13),0,AND(I$41>$C$12,I$42<$C$13),I$42-I$41+1,I$41<=$C$12,I$42-$C$12+1,I$42>=$C$13,$C$13-I$41+1)} -> 0 | J44: {=_xlfn.IFS(AND($C$12>=J$41,$C$13<=J$42),$C$13-$C$12+1,OR(J$42<$C$12,J$41>$C$13),0,AND(J$41>$C$12,J$42<$C$13),J$42-J$41+1,J$41<=$C$12,J$42-$C$12+1,J$42>=$C$13,$C$13-J$41+1)} -> 0 | K44: {=_xlfn.IFS(AND($C$12>=K$41,$C$13<=K$42),$C$13-$C$12+1,OR(K$42<$C$12,K$41>$C$13),0,AND(K$41>$C$12,K$42<$C$13),K$42-K$41+1,K$41<=$C$12,K$42-$C$12+1,K$42>=$C$13,$C$13-K$41+1)} -> 0 | L44: {=_xlfn.IFS(AND($C$12>=L$41,$C$13<=L$42),$C$13-$C$12+1,OR(L$42<$C$12,L$41>$C$13),0,AND(L$41>$C$12,L$42<$C$13),L$42-L$41+1,L$41<=$C$12,L$42-$C$12+1,L$42>=$C$13,$C$13-L$41+1)} -> 0 | M44: {=_xlfn.IFS(AND($C$12>=M$41,$C$13<=M$42),$C$13-$C$12+1,OR(M$42<$C$12,M$41>$C$13),0,AND(M$41>$C$12,M$42<$C$13),M$42-M$41+1,M$41<=$C$12,M$42-$C$12+1,M$42>=$C$13,$C$13-M$41+1)} -> 0 | ... P44: {=_xlfn.IFS(AND($C$12>=P$41,$C$13<=P$42),$C$13-$C$12+1,OR(P$42<$C$12,P$41>$C$13),0,AND(P$41>$C$12,P$42<$C$13),P$42-P$41+1,P$41<=$C$12,P$42-$C$12+1,P$42>=$C$13,$C$13-P$41+1)} -> 0
B45: Total Number of Effective Days within CY | F45: =SUM(F$43,F$44) -> 0 | G45: =SUM(G$43,G$44) -> 365 | H45: =SUM(H$43,H$44) -> 0 | I45: =SUM(I$43,I$44) -> 0 | J45: =SUM(J$43,J$44) -> 0 | K45: =SUM(K$43,K$44) -> 0 | L45: =SUM(L$43,L$44) -> 0 | M45: =SUM(M$43,M$44) -> 0 | ... P45: =SUM(P$43,P$44) -> 0
B46: Matching FY Cash Allocation (Jan-Sept) | C46: FY = CY | F46: {=_xlfn.IFS(AND(F$43=0, F$44=0), 0, AND(F$43<>0, F$44<>0), F$43/F$45, F$43=0, 0, F$43<>0, 1)} -> 0 | G46: {=_xlfn.IFS(AND(G$43=0, G$44=0), 0, AND(G$43<>0, G$44<>0), G$43/G$45, G$43=0, 0, G$43<>0, 1)} -> 0.59452055 | H46: {=_xlfn.IFS(AND(H$43=0, H$44=0), 0, AND(H$43<>0, H$44<>0), H$43/H$45, H$43=0, 0, H$43<>0, 1)} -> 0 | I46: {=_xlfn.IFS(AND(I$43=0, I$44=0), 0, AND(I$43<>0, I$44<>0), I$43/I$45, I$43=0, 0, I$43<>0, 1)} -> 0 | J46: {=_xlfn.IFS(AND(J$43=0, J$44=0), 0, AND(J$43<>0, J$44<>0), J$43/J$45, J$43=0, 0, J$43<>0, 1)} -> 0 | K46: {=_xlfn.IFS(AND(K$43=0, K$44=0), 0, AND(K$43<>0, K$44<>0), K$43/K$45, K$43=0, 0, K$43<>0, 1)} -> 0 | L46: {=_xlfn.IFS(AND(L$43=0, L$44=0), 0, AND(L$43<>0, L$44<>0), L$43/L$45, L$43=0, 0, L$43<>0, 1)} -> 0 | M46: {=_xlfn.IFS(AND(M$43=0, M$44=0), 0, AND(M$43<>0, M$44<>0), M$43/M$45, M$43=0, 0, M$43<>0, 1)} -> 0 | ... P46: {=_xlfn.IFS(AND(P$43=0, P$44=0), 0, AND(P$43<>0, P$44<>0), P$43/P$45, P$43=0, 0, P$43<>0, 1)} -> 0
B47: Next FY Cash Allocation (Oct-Dec) | C47: FY = CY + 1 | F47: {=_xlfn.IFS(AND(F$43=0, F$44=0), 0, AND(F$43<>0, F$44<>0), F$44/F$45, F$44=0, 0, F$44<>0, 1)} -> 0 | G47: {=_xlfn.IFS(AND(G$43=0, G$44=0), 0, AND(G$43<>0, G$44<>0), G$44/G$45, G$44=0, 0, G$44<>0, 1)} -> 0.40547945 | H47: {=_xlfn.IFS(AND(H$43=0, H$44=0), 0, AND(H$43<>0, H$44<>0), H$44/H$45, H$44=0, 0, H$44<>0, 1)} -> 0 | I47: {=_xlfn.IFS(AND(I$43=0, I$44=0), 0, AND(I$43<>0, I$44<>0), I$44/I$45, I$44=0, 0, I$44<>0, 1)} -> 0 | J47: {=_xlfn.IFS(AND(J$43=0, J$44=0), 0, AND(J$43<>0, J$44<>0), J$44/J$45, J$44=0, 0, J$44<>0, 1)} -> 0 | K47: {=_xlfn.IFS(AND(K$43=0, K$44=0), 0, AND(K$43<>0, K$44<>0), K$44/K$45, K$44=0, 0, K$44<>0, 1)} -> 0 | L47: {=_xlfn.IFS(AND(L$43=0, L$44=0), 0, AND(L$43<>0, L$44<>0), L$44/L$45, L$44=0, 0, L$44<>0, 1)} -> 0 | M47: {=_xlfn.IFS(AND(M$43=0, M$44=0), 0, AND(M$43<>0, M$44<>0), M$44/M$45, M$44=0, 0, M$44<>0, 1)} -> 0 | ... P47: {=_xlfn.IFS(AND(P$43=0, P$44=0), 0, AND(P$43<>0, P$44<>0), P$44/P$45, P$44=0, 0, P$44<>0, 1)} -> 0
B49: 2b) Allocate FFS CY Incurred Spending to FY Cash as an Amount
...

Sheet License
